Workbook

Sheet Resumen
A2: Revisión manual del benchmark AgroRAG
A3: Complete los campos amarillos. La revisión humana debe evaluar estado, contenido factual y citas.
A5: Revisor | D5: Métrica | E5: Resultado | G5: Avance
A6: Fecha de revisión | D6: Casos totales | E6: =COUNTA(Casos!$A$6:$A$65) -> 60 | G6: Porcentaje completo | H6: =IF(E6=0,0,E7/E6) -> 0.016666667
A7: Commit evaluado | B7: 478cbe2 | D7: Casos completados | E7: =COUNTA(Casos!$O$6:$O$65) -> 1 | G7: Estado | H7: =IF(E8=0,"COMPLETO","PENDIENTE") -> PENDIENTE
A8: Modelo o proveedor | D8: Casos pendientes | E8: =E6-E7 -> 59
A9: Fuente de casos | B9: benchmark-60-draft.jsonl | D9: PASS | E9: =COUNTIFS(Casos!$O$6:$O$65,"PASS") -> 1
D10: FAIL | E10: =COUNTIFS(Casos!$O$6:$O$65,"FAIL") -> 0
D11: DUDOSO | E11: =COUNTIFS(Casos!$O$6:$O$65,"DUDOSO") -> 0
A12: Criterios de revisión
A13: 1. Ejecute la pregunta en la app y registre el estado observado y la respuesta visible.
A14: 2. Marque Revisión factual PASS sólo si las afirmaciones coinciden con la respuesta de referencia y el corpus.
A15: 3. Marque Revisión de citas PASS sólo si las fuentes citadas respaldan las afirmaciones. Use NO APLICA cuando el sistema aclara o se abstiene.
A16: 4. Resultado general PASS exige estado correcto, contenido factual correcto y citas correctas cuando corresponden.
A17: 5. Use DUDOSO cuando la etiqueta esperada o la evidencia requieran una segunda revisión.
A18: 6. Al terminar, adjunte este archivo. No cambie query_id ni los datos fuente de las columnas A:J.
A21: Estado esperado | B21: Total | C21: Completados | D21: PASS
A22: answered | B22: =COUNTIFS(Casos!$F$6:$F$65,$A22) -> 36 | C22: =COUNTIFS(Casos!$F$6:$F$65,$A22,Casos!$O$6:$O$65,"<>") -> 1 | D22: =COUNTIFS(Casos!$F$6:$F$65,$A22,Casos!$O$6:$O$65,"PASS") -> 1
A23: needs_clarification | B23: =COUNTIFS(Casos!$F$6:$F$65,$A23) -> 12 | C23: =COUNTIFS(Casos!$F$6:$F$65,$A23,Casos!$O$6:$O$65,"<>") -> 0 | D23: =COUNTIFS(Casos!$F$6:$F$65,$A23,Casos!$O$6:$O$65,"PASS") -> 0
A24: insufficient_evidence | B24: =COUNTIFS(Casos!$F$6:$F$65,$A24) -> 12 | C24: =COUNTIFS(Casos!$F$6:$F$65,$A24,Casos!$O$6:$O$65,"<>") -> 0 | D24: =COUNTIFS(Casos!$F$6:$F$65,$A24,Casos!$O$6:$O$65,"PASS") -> 0
A25: TOTAL | B25: =SUM(B22:B24) -> 60 | C25: =SUM(C22:C24) -> 1 | D25: =SUM(D22:D24) -> 1

Sheet Casos
A2: Casos para revisión manual
A3: Complete únicamente las columnas amarillas K:Q. Use filtros para revisar por split, categoría o resultado.
A5: query_id | B5: split | C5: category | D5: crop | E5: question | F5: expected_status | G5: reference_answer | H5: required_claims | I5: source_pages | J5: evidence_ids | K5: observed_status | L5: observed_answer | M5: factual_review | N5: citation_review | O5: overall_result | P5: issue_type | Q5: notes | R5: reviewer | S5: review_date | T5: review_status
A6: dev-r-001 | B6: dev | C6: respondable | D6: lettuce | E6: ¿Qué temperaturas favorecen el desarrollo de la lechuga? | F6: answered | G6: La lechuga se desarrolla bien con promedios mensuales de 13 a 18 °C; el rango citado es de 7 a 24 °C y temperaturas superiores a 30 °C perjudican la germinación y el desarrollo. | H6: El promedio mensual favorable es de 13 a 18 °C. Temperaturas superiores a 30 °C perjudican el cultivo. | I6: INTA-HUERTA-2008:69 | J6: df3b22180f03865d9b37eeb3ad74c72d84b6cd2fed74fc3122a417a42a842c8d | K6: answered | L6: Página PDF 69 · página impresa 67 · 1a edición, 2008 Clima y Suelo La lechuga se desarrolla bien en climas templados frescos, con tempe- raturas promedio mensuales comprendidas entre 13o y 18oC, con un rango que puede oscilar entre 7o y 24oC, variación que permite su cul- tivo durante todo el año, utilizando las variedades adecuadas. La temperatura alta, principalmente aquella que supera los 30oC, es el factor más importante que gravita negativamente en la germinación y el posterior desarrollo del cultivo, condicionando el crecimiento. En cuanto a las características del suelo, los que mejor se adaptan son los de alta fertilidad (alto contenido de materia orgánica), de buen dre- naje con alta capacidad de retención de humedad y una acidez neutra. | M6: PASS | N6: PASS | O6: PASS | P6: SIN PROBLEMA | R6: =IF($O6="","",Resumen!$B$5) -> 0 | S6: =IF($O6="","",Resumen!$B$6) -> 0 | T6: =IF($O6="","PENDIENTE",IF($O6="PASS","REVISADO - PASS",IF($O6="FAIL","REVISADO - FAIL","REQUIERE REVISIÓN"))) -> REVISADO - PASS
A7: dev-r-002 | B7: dev | C7: respondable | D7: lettuce | E7: ¿Por qué una temperatura mayor a 30 °C es problemática para la lechuga? | F7: answered | G7: Porque la temperatura alta, especialmente por encima de 30 °C, afecta negativamente la germinación y el desarrollo posterior, condicionando el crecimiento. | H7: Más de 30 °C afecta la germinación. La temperatura alta condiciona el crecimiento posterior. | I7: INTA-HUERTA-2008:69 | J7: df3b22180f03865d9b37eeb3ad74c72d84b6cd2fed74fc3122a417a42a842c8d | M7: PENDIENTE | N7: PENDIENTE | R7: =IF($O7="","",Resumen!$B$5) | S7: =IF($O7="","",Resumen!$B$6) | T7: =IF($O7="","PENDIENTE",IF($O7="PASS","REVISADO - PASS",IF($O7="FAIL","REVISADO - FAIL","REQUIERE REVISIÓN"))) -> PENDIENTE
A8: dev-r-003 | B8: dev | C8: respondable | D8: lettuce | E8: ¿Qué métodos de riego se mencionan para la lechuga? | F8: answered | G8: Se mencionan riego por surco, inundación, aspersión, localizado, gravitacional por pulso y goteo; la elección depende del sistema y la zona de producción. | H8: El corpus menciona surco, inundación, aspersión y riego localizado. También menciona riego gravitacional por pulso y goteo. | I8: INTA-HUERTA-2008:72 INTA-LECHUGA-2022:40 | J8: 2af04baa4eb101bcbd21f58aeeaf8c813d1b538f607163245e255b25beababe5 8eda9b1a3456cede493fadcb22c3baf3f33036c34ae4cffb1465d44512ecfa9c | M8: PENDIENTE | N8: PENDIENTE | R8: =IF($O8="","",Resumen!$B$5) | S8: =IF($O8="","",Resumen!$B$6) | T8: =IF($O8="","PENDIENTE",IF($O8="PASS","REVISADO - PASS",IF($O8="FAIL","REVISADO - FAIL","REQUIERE REVISIÓN"))) -> PENDIENTE
A9: dev-r-004 | B9: dev | C9: respondable | D9: lettuce | E9: ¿El corpus contempla riego por aspersión y por goteo en lechuga? | F9: answered | G9: Sí. Las fuentes enumeran la aspersión y el riego por goteo entre los sistemas utilizados en lechuga. | H9: La aspersión está mencionada para lechuga. El goteo está mencionado para lechuga. | I9: INTA-HUERTA-2008:72 INTA-LECHUGA-2022:40 | J9: 2af04baa4eb101bcbd21f58aeeaf8c813d1b538f607163245e255b25beababe5 8eda9b1a3456cede493fadcb22c3baf3f33036c34ae4cffb1465d44512ecfa9c | M9: PENDIENTE | N9: PENDIENTE | R9: =IF($O9="","",Resumen!$B$5) | S9: =IF($O9="","",Resumen!$B$6) | T9: =IF($O9="","PENDIENTE",IF($O9="PASS","REVISADO - PASS",IF($O9="FAIL","REVISADO - FAIL","REQUIERE REVISIÓN"))) -> PENDIENTE
A10: dev-r-005 | B10: dev | C10: respondable | D10: tomato | E10: ¿Qué nivel de humedad del suelo se recomienda para el tomate? | F10: answered | G10: La fuente recomienda mantener el suelo cerca del 70 % de su capacidad de retención máxima. | H10: La recomendación citada es 70 % de la capacidad de retención máxima. | I10: INTA-HUERTA-2008:103 | J10: 354faf3532b9536270b9f42f380fcbb1d53de7f3d9b57a5d0d64ca8310e90c78 | M10: PENDIENTE | N10: PENDIENTE | R10: =IF($O10="","",Resumen!$B$5) | S10: =IF($O10="","",Resumen!$B$6) | T10: =IF($O10="","PENDIENTE",IF($O10="PASS","REVISADO - PASS",IF($O10="FAIL","REVISADO - FAIL","REQUIERE REVISIÓN"))) -> PENDIENTE
A11: dev-r-006 | B11: dev | C11: respondable | D11: tomato | E11: ¿Qué riesgos tiene regar tomate por encima de la capacidad de retención del suelo? | F11: answered | G11: El exceso dificulta la respiración de las raíces, desperdicia agua y puede lavar sustancias que aportan fertilidad al suelo. | H11: El exceso de agua dificulta la respiración radicular. Puede provocar lavado de sustancias fértiles. | I11: INTA-HUERTA-2008:103 | J11: 354faf3532b9536270b9f42f380fcbb1d53de7f3d9b57a5d0d64ca8310e90c78 | M11: PENDIENTE | N11: PENDIENTE | R11: =IF($O11="","",Resumen!$B$5) | S11: =IF($O11="","",Resumen!$B$6) | T11: =IF($O11="","PENDIENTE",IF($O11="PASS","REVISADO - PASS",IF($O11="FAIL","REVISADO - FAIL","REQUIERE REVISIÓN"))) -> PENDIENTE
A12: dev-r-007 | B12: dev | C12: respondable | D12: tomato | E12: ¿Cuál es el período crítico del tomate frente a la falta de agua? | F12: answered | G12: El cuajado de frutos es crítico; otra fuente amplía la precaución desde el inicio de floración hasta la maduración y recomienda mantener humedad suficiente durante floración y cuaje. | H12: El cuajado de frutos es un período crítico. La frecuencia debe cuidarse desde floración hasta maduración. | I12: INTA-HUERTA-2008:131 INTA-TOMATE-2020:3 INTA-TOMATE-2020:4 | J12: 1c3ab87a9119e10257d9fd41118008571b57546a5381add1af3d121d1a858615 e107e0e395b514cf76601a4052c41499fae88601fcfaa590a500f9c91038cebb 1ed39f3ff9bd393ca12706a45d8bedfba306f477cefd008e0236b9db3855c612 | M12: PENDIENTE | N12: PENDIENTE | R12: =IF($O12="","",Resumen!$B$5) | S12: =IF($O12="","",Resumen!$B$6) | T12: =IF($O12="","PENDIENTE",IF($O12="PASS","REVISADO - PASS",IF($O12="FAIL","REVISADO - FAIL","REQUIERE REVISIÓN"))) -> PENDIENTE
A13: dev-r-008 | B13: dev | C13: respondable | D13: tomato | E13: ¿Desde qué etapa conviene aumentar la frecuencia de riego del tomate? | F13: answered | G13: La fuente indica aumentar la frecuencia al inicio de la floración y mantenerla hasta la maduración del fruto, con atención especial a floración y cuaje. | H13: La frecuencia aumenta al inicio de floración. Se mantiene hasta la maduración del fruto. | I13: INTA-TOMATE-2020:3 INTA-TOMATE-2020:4 | J13: e107e0e395b514cf76601a4052c41499fae88601fcfaa590a500f9c91038cebb 1ed39f3ff9bd393ca12706a45d8bedfba306f477cefd008e0236b9db3855c612 | M13: PENDIENTE | N13: PENDIENTE | R13: =IF($O13="","",Resumen!$B$5) | S13: =IF($O13="","",Resumen!$B$6) | T13: =IF($O13="","PENDIENTE",IF($O13="PASS","REVISADO - PASS",IF($O13="FAIL","REVISADO - FAIL","REQUIERE REVISIÓN"))) -> PENDIENTE
A14: dev-r-009 | B14: dev | C14: respondable | E14: ¿Qué es la evapotranspiración? | F14: answered | G14: Es la combinación de la evaporación desde el suelo y la transpiración desde las plantas, procesos que ocurren simultáneamente. | H14: La evapotranspiración combina evaporación y transpiración. Ambos procesos ocurren simultáneamente. | I14: FAO56-1998:27 INTA-RIEGO-HORTICOLAS-2024:3 | J14: 61bc6dbe976723de26b81cf82c196d5533a294c43ed83d6f8d73f1e95c1bda5e 06eb01883972c6d861772a560f2202d81f38d5f66990e60827d9aed83cab5961 | M14: PENDIENTE | N14: PENDIENTE | R14: =IF($O14="","",Resumen!$B$5) | S14: =IF($O14="","",Resumen!$B$6) | T14: =IF($O14="","PENDIENTE",IF($O14="PASS","REVISADO - PASS",IF($O14="FAIL","REVISADO - FAIL","REQUIERE REVISIÓN"))) -> PENDIENTE
A15: dev-r-010 | B15: dev | C15: respondable | E15: ¿Qué dos pérdidas de agua integran la ET? | F15: answered | G15: La ET integra la evaporación del agua desde el suelo y la transpiración del agua desde las hojas o tejidos vegetales. | H15: Una componente es la evaporación del suelo. La otra componente es la transpiración vegetal. | I15: FAO56-1998:27 INTA-RIEGO-HORTICOLAS-2024:3 | J15: 61bc6dbe976723de26b81cf82c196d5533a294c43ed83d6f8d73f1e95c1bda5e 06eb01883972c6d861772a560f2202d81f38d5f66990e60827d9aed83cab5961 | M15: PENDIENTE | N15: PENDIENTE | R15: =IF($O15="","",Resumen!$B$5) | S15: =IF($O15="","",Resumen!$B$6) | T15: =IF($O15="","PENDIENTE",IF($O15="PASS","REVISADO - PASS",IF($O15="FAIL","REVISADO - FAIL","REQUIERE REVISIÓN"))) -> PENDIENTE
A16: dev-r-011 | B16: dev | C16: respondable | E16: ¿Por qué estructuras pierden principalmente agua los cultivos? | F16: answered | G16: Los cultivos pierden principalmente agua por los estomas, pequeñas aberturas de las hojas por donde pasan gases y vapor de agua. | H16: La pérdida principal ocurre por los estomas. Los estomas son aberturas en las hojas. | I16: FAO56-1998:29 | J16: 329cdac0e9de37a402dc2e2284790b316d99dd23cfc2d62a6cba023ed0c3a7c3 | M16: PENDIENTE | N16: PENDIENTE | R16: =IF($O16="","",Resumen!$B$5) | S16: =IF($O16="","",Resumen!$B$6) | T16: =IF($O16="","PENDIENTE",IF($O16="PASS","REVISADO - PASS",IF($O16="FAIL","REVISADO - FAIL","REQUIERE REVISIÓN"))) -> PENDIENTE
A17: dev-r-012 | B17: dev | C17: respondable | E17: ¿Qué factores se deben considerar al evaluar la transpiración? | F17: answered | G17: Se consideran radiación, temperatura del aire, humedad, viento, contenido de agua del suelo, capacidad de conducir agua a las raíces, anegamiento, salinidad y características del cultivo y manejo. | H17: Radiación, temperatura, humedad y viento influyen en la transpiración. También influyen el agua del suelo, la salinidad y el cultivo. | I17: FAO56-1998:29 | J17: 329cdac0e9de37a402dc2e2284790b316d99dd23cfc2d62a6cba023ed0c3a7c3 7ce0d2d3dac5db8b84e4ce2b86f547337c45a057562aea5e2378782441a4578f | M17: PENDIENTE | N17: PENDIENTE | R17: =IF($O17="","",Resumen!$B$5) | S17: =IF($O17="","",Resumen!$B$6) | T17: =IF($O17="","PENDIENTE",IF($O17="PASS","REVISADO - PASS",IF($O17="FAIL","REVISADO - FAIL","REQUIERE REVISIÓN"))) -> PENDIENTE
A18: dev-r-013 | B18: dev | C18: respondable | E18: ¿Qué significan capacidad de campo y punto de marchitez permanente? | F18: answered | G18: La capacidad de campo es el agua que el suelo retiene contra la gravedad después de saturarse; el punto de marchitez permanente es el agua remanente que las plantas ya no pueden extraer. | H18: La capacidad de campo es agua retenida contra la gravedad. En el punto de marchitez la planta ya no extrae agua. | I18: FAO56-1998:187 INTA-RIEGO-HORTICOLAS-2024:6 | J18: 7a7407cdc6817ec98a075e75d7541899aca7d2e58e8ecf8cd71288aba7301284 cfea1e355bbc343d7c0fba4cfb2378959d327a0b96ee265d0916b783dcb1937a | M18: PENDIENTE | N18: PENDIENTE | R18: =IF($O18="","",Resumen!$B$5) | S18: =IF($O18="","",Resumen!$B$6) | T18: =IF($O18="","PENDIENTE",IF($O18="PASS","REVISADO - PASS",IF($O18="FAIL","REVISADO - FAIL","REQUIERE REVISIÓN"))) -> PENDIENTE
A19: dev-r-014 | B19: dev | C19: respondable | E19: ¿Cómo se define el agua disponible total en el suelo? | F19: answered | G19: El agua disponible total es la diferencia entre la capacidad de campo y el punto de marchitez permanente. | H19: ADT se calcula como capacidad de campo menos punto de marchitez permanente. | I19: FAO56-1998:187 INTA-RIEGO-HORTICOLAS-2024:6 | J19: 7a7407cdc6817ec98a075e75d7541899aca7d2e58e8ecf8cd71288aba7301284 cfea1e355bbc343d7c0fba4cfb2378959d327a0b96ee265d0916b783dcb1937a | M19: PENDIENTE | N19: PENDIENTE | R19: =IF($O19="","",Resumen!$B$5) | S19: =IF($O19="","",Resumen!$B$6) | T19: =IF($O19="","PENDIENTE",IF($O19="PASS","REVISADO - PASS",IF($O19="FAIL","REVISADO - FAIL","REQUIERE REVISIÓN"))) -> PENDIENTE
A20: dev-r-015 | B20: dev | C20: respondable | E20: ¿Qué variables meteorológicas se consideran para ajustar la programación del riego? | F20: answered | G20: La programación debe ajustarse con la temperatura, humedad, precipitación, viento y radiación del ciclo en curso. | H20: Se consideran temperatura, humedad y precipitación. También se consideran viento y radiación. | I20: INTA-RIEGO-HORTICOLAS-2024:12 | J20: 5208387d04bc77975d5d325ba305cacb936129ea760c2795efb54de887f6a59c | M20: PENDIENTE | N20: PENDIENTE | R20: =IF($O20="","",Resumen!$B$5) | S20: =IF($O20="","",Resumen!$B$6) | T20: =IF($O20="","PENDIENTE",IF($O20="PASS","REVISADO - PASS",IF($O20="FAIL","REVISADO - FAIL","REQUIERE REVISIÓN"))) -> PENDIENTE
A21: dev-r-016 | B21: dev | C21: respondable | E21: ¿Cómo puede monitorearse la humedad o retención de agua del suelo? | F21: answered | G21: La humedad puede determinarse directamente por método gravimétrico o indirectamente con sensores; la energía de retención puede medirse con tensiómetros o bloques de yeso. | H21: El método gravimétrico y los sensores permiten estimar humedad. Tensiómetros o bloques de yeso permiten evaluar retención. | I21: INTA-RIEGO-HORTICOLAS-2024:12 | J21: 2e57dd332312bf09447cb2b8aed7d4833e509b06bf2334ef72e73cd94fe46214 | M21: PENDIENTE | N21: PENDIENTE | R21: =IF($O21="","",Resumen!$B$5) | S21: =IF($O21="","",Resumen!$B$6) | T21: =IF($O21="","PENDIENTE",IF($O21="PASS","REVISADO - PASS",IF($O21="FAIL","REVISADO - FAIL","REQUIERE REVISIÓN"))) -> PENDIENTE
A22: dev-r-017 | B22: dev | C22: respondable | D22: lettuce | E22: ¿Qué conductividad eléctrica del agua se recomienda no superar para lechuga? | F22: answered | G22: La fuente recomienda mantener la conductividad eléctrica del agua de riego por debajo de 0,9 dS/m; a 1,4 dS/m el rendimiento potencial disminuye 10 %. | H22: La CE del agua debería ser menor a 0,9 dS/m. A 1,4 dS/m se informa una disminución potencial de 10 %. | I22: INTA-LECHUGA-2022:28 | J22: 90b1847529581acb386fb07c78121faece5e3ec7fae3fcce6b08c16f5e8d9084 | M22: PENDIENTE | N22: PENDIENTE | R22: =IF($O22="","",Resumen!$B$5) | S22: =IF($O22="","",Resumen!$B$6) | T22: =IF($O22="","PENDIENTE",IF($O22="PASS","REVISADO - PASS",IF($O22="FAIL","REVISADO - FAIL","REQUIERE REVISIÓN"))) -> PENDIENTE
A23: dev-r-018 | B23: dev | C23: respondable | D23: lettuce | E23: ¿Cómo afecta la salinidad a la absorción de agua en lechuga? | F23: answered | G23: Las sales elevan la presión osmótica y dificultan que la planta absorba agua, pudiendo causar sequía fisiológica y efectos tóxicos. | H23: La salinidad aumenta la presión osmótica. Puede dificultar la absorción y causar sequía fisiológica. | I23: INTA-LECHUGA-2022:28 | J23: 90b1847529581acb386fb07c78121faece5e3ec7fae3fcce6b08c16f5e8d9084 | M23: PENDIENTE | N23: PENDIENTE | R23: =IF($O23="","",Resumen!$B$5) | S23: =IF($O23="","",Resumen!$B$6) | T23: =IF($O23="","PENDIENTE",IF($O23="PASS","REVISADO - PASS",IF($O23="FAIL","REVISADO - FAIL","REQUIERE REVISIÓN"))) -> PENDIENTE
A24: dev-u-001 | B24: dev | C24: unsupported | D24: tomato | E24: ¿Qué dosis exacta de nitrógeno por hectárea se recomienda para tomate? | F24: insufficient_evidence | M24: PENDIENTE | N24: PENDIENTE | R24: =IF($O24="","",Resumen!$B$5) | S24: =IF($O24="","",Resumen!$B$6) | T24: =IF($O24="","PENDIENTE",IF($O24="PASS","REVISADO - PASS",IF($O24="FAIL","REVISADO - FAIL","REQUIERE REVISIÓN"))) -> PENDIENTE
A25: dev-u-002 | B25: dev | C25: unsupported | D25: tomato | E25: ¿Qué insecticida y dosis debo aplicar contra mosca blanca? | F25: insufficient_evidence | M25: PENDIENTE | N25: PENDIENTE | R25: =IF($O25="","",Resumen!$B$5) | S25: =IF($O25="","",Resumen!$B$6) | T25: =IF($O25="","PENDIENTE",IF($O25="PASS","REVISADO - PASS",IF($O25="FAIL","REVISADO - FAIL","REQUIERE REVISIÓN"))) -> PENDIENTE
A26: dev-u-003 | B26: dev | C26: unsupported | D26: lettuce | E26: ¿Cuántas toneladas por hectárea rendirá mi cultivo de lechuga? | F26: insufficient_evidence | M26: PENDIENTE | N26: PENDIENTE | R26: =IF($O26="","",Resumen!$B$5) | S26: =IF($O26="","",Resumen!$B$6) | T26: =IF($O26="","PENDIENTE",IF($O26="PASS","REVISADO - PASS",IF($O26="FAIL","REVISADO - FAIL","REQUIERE REVISIÓN"))) -> PENDIENTE
A27: dev-u-004 | B27: dev | C27: unsupported | E27: ¿Va a llover mañana en mi lote? | F27: insufficient_evidence | M27: PENDIENTE | N27: PENDIENTE | R27: =IF($O27="","",Resumen!$B$5) | S27: =IF($O27="","",Resumen!$B$6) | T27: =IF($O27="","PENDIENTE",IF($O27="PASS","REVISADO - PASS",IF($O27="FAIL","REVISADO - FAIL","REQUIERE REVISIÓN"))) -> PENDIENTE
A28: dev-u-005 | B28: dev | C28: unsupported | E28: ¿Qué marca y modelo de sensor de humedad debería comprar? | F28: insufficient_evidence | M28: PENDIENTE | N28: PENDIENTE | R28: =IF($O28="","",Resumen!$B$5) | S28: =IF($O28="","",Resumen!$B$6) | T28: =IF($O28="","PENDIENTE",IF($O28="PASS","REVISADO - PASS",IF($O28="FAIL","REVISADO - FAIL","REQUIERE REVISIÓN"))) -> PENDIENTE
A29: dev-u-006 | B29: dev | C29: unsupported | D29: tomato | E29: ¿Cuál es la variedad comercial de tomate más rentable este año? | F29: insufficient_evidence | M29: PENDIENTE | N29: PENDIENTE | R29: =IF($O29="","",Resumen!$B$5) | S29: =IF($O29="","",Resumen!$B$6) | T29: =IF($O29="","PENDIENTE",IF($O29="PASS","REVISADO - PASS",IF($O29="FAIL","REVISADO - FAIL","REQUIERE REVISIÓN"))) -> PENDIENTE
A30: dev-a-001 | B30: dev | C30: adversarial | E30: ¿Cuánta agua le doy? | F30: needs_clarification | M30: PENDIENTE | N30: PENDIENTE | R30: =IF($O30="","",Resumen!$B$5) | S30: =IF($O30="","",Resumen!$B$6) | T30: =IF($O30="","PENDIENTE",IF($O30="PASS","REVISADO - PASS",IF($O30="FAIL","REVISADO - FAIL","REQUIERE REVISIÓN"))) -> PENDIENTE
A31: dev-a-002 | B31: dev | C31: adversarial | E31: ¿Cada cuánto tengo que regar? | F31: needs_clarification | M31: PENDIENTE | N31: PENDIENTE | R31: =IF($O31="","",Resumen!$B$5) | S31: =IF($O31="","",Resumen!$B$6) | T31: =IF($O31="","PENDIENTE",IF($O31="PASS","REVISADO - PASS",IF($O31="FAIL","REVISADO - FAIL","REQUIERE REVISIÓN"))) -> PENDIENTE
A32: dev-a-003 | B32: dev | C32: adversarial | E32: Las hojas están mal, ¿es por el riego? | F32: needs_clarification | M32: PENDIENTE | N32: PENDIENTE | R32: =IF($O32="","",Resumen!$B$5) | S32: =IF($O32="","",Resumen!$B$6) | T32: =IF($O32="","PENDIENTE",IF($O32="PASS","REVISADO - PASS",IF($O32="FAIL","REVISADO - FAIL","REQUIERE REVISIÓN"))) -> PENDIENTE
A33: dev-a-004 | B33: dev | C33: adversarial | E33: El sensor marca 20, ¿riego ahora? | F33: needs_clarification | M33: PENDIENTE | N33: PENDIENTE | R33: =IF($O33="","",Resumen!$B$5) | S33: =IF($O33="","",Resumen!$B$6) | T33: =IF($O33="","PENDIENTE",IF($O33="PASS","REVISADO - PASS",IF($O33="FAIL","REVISADO - FAIL","REQUIERE REVISIÓN"))) -> PENDIENTE
A34: dev-a-005 | B34: dev | C34: adversarial | E34: ¿Esto es demasiada agua para el cultivo? | F34: needs_clarification | M34: PENDIENTE | N34: PENDIENTE | R34: =IF($O34="","",Resumen!$B$5) | S34: =IF($O34="","",Resumen!$B$6) | T34: =IF($O34="","PENDIENTE",IF($O34="PASS","REVISADO - PASS",IF($O34="FAIL","REVISADO - FAIL","REQUIERE REVISIÓN"))) -> PENDIENTE
A35: dev-a-006 | B35: dev | C35: adversarial | E35: ¿Cuál es el momento crítico? | F35: needs_clarification | M35: PENDIENTE | N35: PENDIENTE | R35: =IF($O35="","",Resumen!$B$5) | S35: =IF($O35="","",Resumen!$B$6) | T35: =IF($O35="","PENDIENTE",IF($O35="PASS","REVISADO - PASS",IF($O35="FAIL","REVISADO - FAIL","REQUIERE REVISIÓN"))) -> PENDIENTE
A36: test-r-001 | B36: test | C36: respondable | D36: lettuce | E36: ¿Cuándo es más crítica la falta de agua en lechuga? | F36: answered | G36: La humedad debe sostenerse durante todo el ciclo, especialmente antes de la cosecha; su sistema radicular reducido hace que no tolere ni períodos breves de sequía. | H36: La humedad es crítica durante todo el ciclo. La atención es especial antes de cosecha. | I36: INTA-HUERTA-2008:131 INTA-LECHUGA-2022:28 | J36: 2bea1c46e7dce68ee23b3d6609270dd5a50d3ce18b1d0795f25f6e9cc4f01288 589be666477a5dc5a77f3a2706564f1dae6b53085d90b88b7bacbdb4a4e607cf | M36: PENDIENTE | N36: PENDIENTE | R36: =IF($O36="","",Resumen!$B$5) | S36: =IF($O36="","",Resumen!$B$6) | T36: =IF($O36="","PENDIENTE",IF($O36="PASS","REVISADO - PASS",IF($O36="FAIL","REVISADO - FAIL","REQUIERE REVISIÓN"))) -> PENDIENTE
A37: test-r-002 | B37: test | C37: respondable | D37: lettuce | E37: ¿Por qué la lechuga es sensible a períodos breves de sequía? | F37: answered | G37: Porque su sistema radicular es muy reducido respecto de la parte aérea, por lo que es susceptible al déficit hídrico durante todo el ciclo. | H37: La lechuga tiene un sistema radicular reducido. Esa condición aumenta su susceptibilidad al déficit hídrico. | I37: INTA-LECHUGA-2022:28 | J37: 589be666477a5dc5a77f3a2706564f1dae6b53085d90b88b7bacbdb4a4e607cf | M37: PENDIENTE | N37: PENDIENTE | R37: =IF($O37="","",Resumen!$B$5) | S37: =IF($O37="","",Resumen!$B$6) | T37: =IF($O37="","PENDIENTE",IF($O37="PASS","REVISADO - PASS",IF($O37="FAIL","REVISADO - FAIL","REQUIERE REVISIÓN"))) -> PENDIENTE
A38: test-r-003 | B38: test | C38: respondable | E38: ¿Qué variables climáticas controlan la evaporación? | F38: answered | G38: La radiación solar, la temperatura del aire, la humedad y la velocidad del viento son variables climáticas centrales para evaluar la evaporación. | H38: Radiación y temperatura influyen en la evaporación. Humedad y viento también influyen. | I38: FAO56-1998:27 | J38: 61bc6dbe976723de26b81cf82c196d5533a294c43ed83d6f8d73f1e95c1bda5e 7c84836214c34dc7fd2c6434c077f328c5207e922455fb613af21eea46c5a2d5 | M38: PENDIENTE | N38: PENDIENTE | R38: =IF($O38="","",Resumen!$B$5) | S38: =IF($O38="","",Resumen!$B$6) | T38: =IF($O38="","PENDIENTE",IF($O38="PASS","REVISADO - PASS",IF($O38="FAIL","REVISADO - FAIL","REQUIERE REVISIÓN"))) -> PENDIENTE
A39: test-r-004 | B39: test | C39: respondable | E39: ¿Qué ocurre con la evaporación cuando la superficie del suelo queda sin aporte de agua? | F39: answered | G39: Cuando se seca la capa superficial y no hay nuevo aporte de agua, la disponibilidad limita el proceso: la evaporación disminuye rápidamente y puede casi cesar en pocos días. | H39: La disponibilidad de agua superficial pasa a controlar la evaporación. Sin aporte, la evaporación puede casi cesar en pocos días. | I39: FAO56-1998:27 | J39: 7c84836214c34dc7fd2c6434c077f328c5207e922455fb613af21eea46c5a2d5 14e7b897c966cc3457e54277f72fd7bfda45b36611a6f9200622202341716cac | M39: PENDIENTE | N39: PENDIENTE | R39: =IF($O39="","",Resumen!$B$5) | S39: =IF($O39="","",Resumen!$B$6) | T39: =IF($O39="","PENDIENTE",IF($O39="PASS","REVISADO - PASS",IF($O39="FAIL","REVISADO - FAIL","REQUIERE REVISIÓN"))) -> PENDIENTE
A40: test-r-005 | B40: test | C40: respondable | E40: ¿Cómo cambia la proporción de evaporación y transpiración a medida que crece el cultivo? | F40: answered | G40: Al inicio predomina la evaporación del suelo; al crecer la cobertura, el suelo recibe menos radiación y la transpiración pasa a dominar. Con cobertura completa, más de 90 % de la ET puede corresponder a transpiración. | H40: Al inicio predomina la evaporación. Con cobertura completa predomina la transpiración. | I40: FAO56-1998:29 INTA-RIEGO-HORTICOLAS-2024:3 | J40: 7ce0d2d3dac5db8b84e4ce2b86f547337c45a057562aea5e2378782441a4578f 92d081dcf1b8418b9362a935e5387b93ddafa36cff169b0cfa59049cd876a98f 06eb01883972c6d861772a560f2202d81f38d5f66990e60827d9aed83cab5961 | M40: PENDIENTE | N40: PENDIENTE | R40: =IF($O40="","",Resumen!$B$5) | S40: =IF($O40="","",Resumen!$B$6) | T40: =IF($O40="","PENDIENTE",IF($O40="PASS","REVISADO - PASS",IF($O40="FAIL","REVISADO - FAIL","REQUIERE REVISIÓN"))) -> PENDIENTE
A41: test-r-006 | B41: test | C41: respondable | E41: ¿Qué fracción de la ET puede provenir de la transpiración con cobertura completa? | F41: answered | G41: La fuente indica que con cobertura completa del cultivo más del 90 % de la evapotranspiración proviene de la transpiración. | H41: Con cobertura completa, más de 90 % de la ET puede ser transpiración. | I41: FAO56-1998:29 | J41: 92d081dcf1b8418b9362a935e5387b93ddafa36cff169b0cfa59049cd876a98f | M41: PENDIENTE | N41: PENDIENTE | R41: =IF($O41="","",Resumen!$B$5) | S41: =IF($O41="","",Resumen!$B$6) | T41: =IF($O41="","PENDIENTE",IF($O41="PASS","REVISADO - PASS",IF($O41="FAIL","REVISADO - FAIL","REQUIERE REVISIÓN"))) -> PENDIENTE
A42: test-r-007 | B42: test | C42: respondable | E42: ¿Qué es el agua fácilmente aprovechable y cómo se relaciona con el factor p? | F42: answered | G42: El agua fácilmente aprovechable es la porción del agua disponible total que el cultivo puede agotar antes de que el estrés reduzca el rendimiento; se obtiene afectando ADT por el factor p. | H42: AFA es una porción de ADT. El factor p representa la fracción agotable antes del estrés que reduce rendimiento. | I42: INTA-RIEGO-HORTICOLAS-2024:6 | J42: cfea1e355bbc343d7c0fba4cfb2378959d327a0b96ee265d0916b783dcb1937a 5881d9222ad259d0a66f38e220a7b4bdcc994382e2f4f51b581c981536de65ea | M42: PENDIENTE | N42: PENDIENTE | R42: =IF($O42="","",Resumen!$B$5) | S42: =IF($O42="","",Resumen!$B$6) | T42: =IF($O42="","PENDIENTE",IF($O42="PASS","REVISADO - PASS",IF($O42="FAIL","REVISADO - FAIL","REQUIERE REVISIÓN"))) -> PENDIENTE
...
